Workbook

Sheet Planilha6
A1: PORTE DO IMÓVEL | B1: FATOR
A2: 50 ha | B2: 0.4
A3: 100 ha | B3: 0.5
A4: 200 ha | B4: 0.6
A5: 500 ha | B5: 0.7
A6: 1000 ha | B6: 0.8
A8: CLASSE DA ÁREA DESMATADA | B8: FATOR
A9: 4 (até 50 ha) | B9: 0.5
A10: 5 (maior eu 50 até 500 ha) | B10: 0.6
A11: 6 (maior que 500 ha) | B11: 0.7
A13: TIPOLOGIA ÁREA DESMATADA | B13: FATOR
A14: Passível | B14: 0.5
A15: Protegidas Permitidas | B15: 0.6
A16: Protegidas Não Permitidas | B16: 0.7
A18: TIPOLOGIA DA COMPENSAÇÃO | B18: FATOR
A19: Florestal | B19: 1
A20: Danos | B20: 2
D24: Valor final: Valor do Pagamento x Hectares Desmatados

Sheet Simuladores 1.0
A1: MUNICÍPIO | D1: SIMULADOR INCRA | L1: CÁLCULO DO TETO
A2: MINACU | D2: VTI MÉDIO/ha | E2: PORTE DO IMÓVEL - FPI | F2: TAMANHO DA ÁREA DESMATADA - FTA | G2: TIPOLOGIA ÁREA DESMATADA - FTA | H2: FATOR | I2: ÁREA A SER COMPENSADA (ha) | J2: VALOR DA COMPENSAÇÃO | L2: 50% do valor total do imovel
A3: Mercados Regionais de Terras-MRT | D3: =SUMIF(#REF!,'Simuladores 1.0'!A4,#REF!) -> #REF! | E3: Pequeno (ate 4 modulos fiscais) | F3: Acima de 50 (cinquenta) e ate 100 (cem) hectares | G3: Passível | H3: 0.3 | I3: 2 | J3: =$D$3*$E$4*$F$4*H3*I3 -> #REF! | L3: CÁLCULO DO PISO
A4: =IFERROR(VLOOKUP(A2,#REF!,2,FALSE()),"Usar simulador Receita") -> Usar simulador Receita | E4: =SUMIF(Fatores!$A:$A,'Simuladores 1.0'!E3,Fatores!$B:$B) -> 0 | F4: =SUMIF(Fatores!$A:$A,'Simuladores 1.0'!F3,Fatores!$B:$B) -> 1.2 | G4: Protegidas Permitidas | J4: =$D$3*$E$4*$F$4*H4*I4 -> #REF! | L4: Cálculo da Compensação | M4: Valor final (R$)
A5: TAMANHO IMÓVEL(ha) | G5: Protegidas Não Permitidas | J5: =$D$3*$E$4*$F$4*H5*I5 -> #REF! | L5: 1 a 1000 | M5: 6500
A6: 35 | I6: TOTAL: | J6: =SUM(J3:J5) -> #REF! | L6: 1001 a 3000 | M6: 6700
A7: MÓDULOS FISCAIS | I7: PISO/TETO? | J7: =IF(J6> (A10/2), A10/2, IF(J6>=7000, J6, IF(J6<=1000, 6500, IF(J6<=3000, 6700, IF(J6<=5000, 6800, IF(J6<=6999, 7000)))))) -> #REF! | L7: 3001 a 5000 | M7: 6800
A8: =(A6/VLOOKUP(A2,Fatores!D:E,2,FALSE())) -> 0.7 | I8: Desconto de 80% | J8: =J7*0.2 -> #REF! | L8: 5001 a 6999 | M8: 7000
A9: VALOR IMÓVEL(ha) -INCRA | I9: Desconto de 20% | J9: =J7*0.8 -> #REF! | L9: 7000 | M9: 7000
A10: =A6*D3 -> #REF!
A11: VALOR IMÓVEL(ha) -RECEITA | D11: SIMULADOR RECEITA
A12: =A6*D14 -> #VALUE! | D12: VALOR DE TERRA NUA/ha | E12: PORTE DO IMÓVEL - FPI | F12: TAMANHO DA ÁREA DESMATADA - FTA | G12: TIPOLOGIA ÁREA DESMATADA - FTA | H12: FATOR | I12: ÁREA A SER COMPENSADA (ha) | J12: VALOR DA COMPENSAÇÃO
D13: Exercício 2024 | E13: Pequeno (ate 4 modulos fiscais) | F13: Acima de 50 (cinquenta) e ate 100 (cem) hectares | G13: Passível | H13: 0.3 | I13: 2 | J13: =$D$14*$E$14*$F$14*H13*I13 -> #VALUE!
D14: =IFERROR(VLOOKUP(A2,#REF!,8,FALSE()),"Município não incluído") -> Município não incluído | E14: =SUMIF(Fatores!$A:$A,'Simuladores 1.0'!E13,Fatores!$B:$B) -> 0 | F14: =SUMIF(Fatores!$A:$A,'Simuladores 1.0'!F13,Fatores!$B:$B) -> 1.2 | G14: Protegidas Permitidas | J14: =$D$14*$E$14*$F$14*H14*I14 -> #VALUE!
G15: Protegidas Não Permitidas | J15: =$D$14*$E$14*$F$14*H15*I15 -> #VALUE!
I16: TOTAL: | J16: =SUM(J13:J15) -> #VALUE!
I17: PISO/TETO? | J17: =IF(J16> (A12/2), A12/2, IF(J16>=7000, J16, IF(J16<=1000, 6500, IF(J16<=3000, 6700, IF(J16<=5000, 6800, IF(J16<=6999, 7000)))))) -> #VALUE!
I18: Desconto de 80% | J18: =J17*0.2 -> #VALUE!
I19: Desconto de 20% | J19: =J17*0.8 -> #VALUE!

Sheet Calculadora Compensação
C2: MUNICÍPIO | E2: SIMULADOR | J2: Compensação por Danos: supressão SEM autorização ou licença - art. 15 (pós 12/2019) da Lei estadual nº 21.231 | M2: Compensação Florestal: supressão SEM autorização ou licença - arts. 14 (pré 12/2019) e 15 (pós 12/2019) da Lei estadual nº 21.231 | R2: Compensação florestal autorizada - arts. 21 e 23 da Lei estadual nº 21.231
E3: VALOR POR HECTARE | F3: FATOR PORTE DO IMÓVEL - FPI | G3: TOTAL DESMATADO/ha | H3: FATOR CLASSE ÁREA DESMATADA - FCA | I3: TIPO DE ÁREA SUPRIMIDA | J3: FATOR MULTIPLICADOR COMPENSAÇÃO POR DANOS ATÉ 12/2019 - FMD-1 | K3: ÁREA SUPRIMIDA (ha) | L3: VALOR PARCIAL CORRESPONDENTE | M3: FATOR MULTIPLICADOR COMPENSAÇÃO FLORESTAL ATÉ 12/2019 - FMF-1 | N3: ÁREA SUPRIMIDA (ha) | O3: VALOR PARCIAL CORRESPONDENTE | P3: VALOR DA COMPENSAÇÃO | R3: FATOR MULTIPLICADOR COMPENSAÇÃO FLORESTAL | S3: ÁREA SUPRIMIDA (ha) | T3: VALOR PARCIAL CORRESPONDENTE
C4: TAMANHO IMÓVEL/ha | E4: Exercício 2024 | F4: =IF(OR(C7="Informar Município",C7<=0),"Informar Município",IF(C7<=4,"Pequeno (ate 4 modulos fiscais)",IF(C7<=15,"Medio (superior a 4 e ate 15 modulos fiscais)","Grande (superior a 15 modulos fiscais)"))) -> Informar Município | H4: =IF(ISBLANK(G4),"Informar total desmatado/ha", IF(G4>C5,"Área desmatada superior ao tamanho do imóvel", IF(G4<=20,"Ate 20 (vinte) hectares", IF(G4<=50,"Acima de 20 (vinte) e ate 50 (cinquenta) hectares", IF(G4<=100,"Acima de 50 (cinquenta) e ate 100 (cem) hectares", IF(G4<=500,"Acima de 100 (cem) e ate 500 (quinhentos) hectares", IF(G4>500,"Acima de 500 (quinhentos) hectares", "Informar Total desmatado/ha"))))))) -> Informar total desmatado/ha | I4: Área Passível | J4: 1 | L4: =IFERROR($E$5*$F$5*$H$5*$J4*$K4,0) -> 0 | M4: 1 | O4: =IFERROR($E$5*$F$5*$H$5*$M4*$N4,0) -> 0 | P4: =L4+O4 -> 0 | R4: 1 | T4: =IFERROR($E$5*$F$5*$H$5*$R4*$S4,0) -> 0
E5: =IFERROR(VLOOKUP(C3,Médias2025!A:D,4,FALSE()),"Indisponível") -> Indisponível | F5: =IFERROR(SUMIF(Fatores!$A:$A,'Calculadora Compensação'!F4,Fatores!$B:$B),"-") -> 0 | H5: =SUMIF(Fatores!$A:$A,'Calculadora Compensação'!H4,Fatores!$B:$B) -> 0 | I5: APP/ uso restrito com intervenção permitida por lei - atividade ou obra de utilidade pública ou interesse social. Lei nº 12.651/2012, art. 3º, IX, alíneas e), f), g). | J5: 1 | L5: =IFERROR($E$5*$F$5*$H$5*$J5*$K5,0) -> 0 | M5: 1 | O5: =IFERROR($E$5*$F$5*$H$5*$M5*$N5,0) -> 0 | P5: =L5+O5 -> 0 | R5: 1 | T5: =IFERROR($E$5*$F$5*$H$5*$R5*$S5,0) -> 0
C6: MÓDULOS FISCAIS | I6: APP/ uso restrito com intervenção permitida por lei - atividade ou obra de baixo impacto ou interesse social. Lei nº 12.651/2012, art. 3º, IX, alíneas a), b), c), d).
C7: =IFERROR(IF((C5/VLOOKUP(C3,Fatores!D:E,2,FALSE()))<1,1,(C5/VLOOKUP(C3,Fatores!D:E,2,FALSE()))),"Informar Município") -> Informar Município | E7: ADEQUAÇÃO DE VALORES | F7: PISOS PARA COMPENSAÇÃO REALIZADAS SEM AUTORIZAÇÃO OU LICENÇA POR HECTARE DEVIDO | I7: APP/ uso restrito com intervenção NÃO permitida por lei. | J7: 2 | L7: =IFERROR($E$5*$F$5*$H$5*$J7*$K7,0) -> 0 | M7: 1 | O7: =IFERROR($E$5*$F$5*$H$5*$M7*$N7,0) -> 0 | P7: =L7+O7 -> 0
C8: VALOR IMÓVEL/ha - MÉDIAS | E8: Porte Pequeno | F8: Porte Médio | G8: Porte Grande | I8: RL com intervenção permitida por lei. Lei nº 12.651/2012, art. 3º, IX, alíneas a), b), c), d) ou pesquisa científica.
C9: =IFERROR(C5*VLOOKUP(C3,Médias2025!A:D,4,FALSE()),"Informar Município") -> Informar Município | E9: 3500 | F9: 7000 | G9: 14000 | I9: RL com intervenção permitida por lei: utilidade pública e interesse social conforme Lei nº 12.651/2012, art. 3º, IX, alíneas e), f), g), exploração mineral ou construção de barragens mediante licenciamento. | J9: 1 | L9: =IFERROR($E$5*$F$5*$H$5*$J9*$K9,0) -> 0 | P9: =L9+O9 -> 0 | R9: 1 | T9: =IFERROR($E$5*$F$5*$H$5*$R9*$S9,0) -> 0
C10: CÁLCULO DO VALOR DO TETO | E10: ADEQUAÇÃO DE VALORES | F10: PISOS PARA COMPENSAÇÃO FLORESTAL AUTORIZADA POR HECTARE DEVIDO | I10: RL com intervenção NÃO permitida por lei. | J10: 1 | L10: =IFERROR($E$5*$F$5*$H$5*$J10*$K10,0) -> 0 | P10: =L10+O10 -> 0
C11: =IF(F4="Pequeno (ate 4 modulos fiscais)",C9*0.5,IF(F4="Medio (superior a 4 e ate 15 modulos fiscais)",C9*0.65,(IF(F4="Grande (superior a 15 modulos fiscais)",C9*0.8,"Informar Município")))) -> Informar Município | E11: Porte Pequeno | F11: Porte Médio | G11: Porte Grande | I11: UC integral que admita supressão de vegetação nativa. | J11: 2 | L11: =IFERROR($E$5*$F$5*$H$5*$J11*$K11,0) -> 0 | M11: 1 | O11: =IFERROR($E$5*$F$5*$H$5*$M11*$N11,0) -> 0 | P11: =L11+O11 -> 0
E12: 1750 | F12: 3500 | G12: 7000 | I12: UC integral que admita supressão de vegetação nativa, obrigatoriamente para implantação de obras ou serviços de utilidade pública. | R12: 2 | T12: =IFERROR($E$5*$F$5*$H$5*$R12*$S12,0) -> 0
E13: ADEQUAÇÃO DE VALORES | F13: TETO PARA TODAS AS HIPÓTESES | I13: UC integral que NÃO admita supressão de vegetação nativa. | J13: 3 | L13: =IFERROR($E$5*$F$5*$H$5*$J13*$K13,0) -> 0 | P13: =L13+O13 -> 0
E14: Porte Pequeno | F14: Porte Médio | G14: Porte Grande | I14: UC de uso sustentável que admita supressão de vegetação nativa. | J14: 1 | L14: =IFERROR($E$5*$F$5*$H$5*$J14*$K14,0) -> 0 | M14: 1 | O14: =IFERROR($E$5*$F$5*$H$5*$M14*$N14,0) -> 0 | P14: =L14+O14 -> 0 | R14: 1 | T14: =IFERROR($E$5*$F$5*$H$5*$R14*$S14,0) -> 0
E15: 50% do valor do imóvel | F15: 65% do valor do imóvel | G15: 80% do valor do imóvel | I15: UC de uso sustentável que NÃO admita supressão de vegetação nativa. | J15: 3 | L15: =IFERROR($E$5*$F$5*$H$5*$J15*$K15,0) -> 0 | P15: =L15+O15 -> 0
I16: UC de uso sustentável que NÃO admita supressão de vegetação nativa, obrigatoriamente para conversão do uso do solo mediante utilidade pública e interesse social. | R16: 1 | T16: =IFERROR($E$5*$F$5*$H$5*$R16*$S16,0) -> 0
I17: APA em zona que admita supressão de vegetação nativa, conforme Plano de Manejo. | J17: 1 | L17: =IFERROR($E$5*$F$5*$H$5*$J17*$K17,0) -> 0 | M17: 1 | O17: =IFERROR($E$5*$F$5*$H$5*$M17*$N17,0) -> 0 | P17: =L17+O17 -> 0 | R17: 1 | T17: =IFERROR($E$5*$F$5*$H$5*$R17*$S17,0) -> 0
I18: APA em zona que NÃO admita supressão de vegetação nativa, conforme Plano de Manejo. | J18: 2 | L18: =IFERROR($E$5*$F$5*$H$5*$J18*$K18,0) -> 0 | P18: =L18+O18 -> 0
I19: Zona de Amortecimento. | J19: 1.5 | L19: =IFERROR($E$5*$F$5*$H$5*$J19*$K19,0) -> 0 | M19: 1 | O19: =IFERROR($E$5*$F$5*$H$5*$M19*$N19,0) -> 0 | P19: =L19+O19 -> 0 | R19: 1 | T19: =IFERROR($E$5*$F$5*$H$5*$M15*$N15,0) -> 0
O20: CÁLCULO INICIAL | P20: =P4+P5+P7+P9+P10+P11+P13+P14+P15+P17+P18+P19 -> 0 | S20: CÁLCULO INICIAL | T20: =T4+T5+T9+T12+T14+T16+T17+T19 -> 0
O21: APLICAÇÃO DO PISO, SE HOUVER | P21: =IF(F4="Pequeno (ate 4 modulos fiscais)", IF(P20 > 3500*P23, "Não se aplica", 3500*P23), IF(F4="Medio (superior a 4 e ate 15 modulos fiscais)", IF(P20 > 7000*P23,"Não se aplica", 7000*P23), IF(F4="Grande (superior a 15 modulos fiscais)", IF(P20 > 14000*P23, "Não se aplica", 14000*P23), "Não se aplica"))) -> Não se aplica | S21: APLICAÇÃO DO PISO, SE HOUVER | T21: =IF(F4="Pequeno (ate 4 modulos fiscais)", IF(T20 >1750*T23, "Não se aplica",1750*T23), IF(F4="Medio (superior a 4 e ate 15 modulos fiscais)", IF(T20 > 3500*P23,"Não se aplica", 3500*T23), IF(F4="Grande (superior a 15 modulos fiscais)", IF(T20 > 7000*T23, "Não se aplica", 7000*T23), "Não se aplica"))) -> Não se aplica
O22: APLICAÇÃO DO TETO, SE HOUVER | P22: =IF( P21>C11,C11, IF( P20>C11,C11,"Não se aplica")) -> Informar Município | S22: APLICAÇÃO DO TETO, SE HOUVER | T22: =IF(T21>C11,C11, IF(T20>C11,C11,"Não se aplica")) -> Informar Município
O23: HECTARES DEVIDOS | P23: =J4*K4+J5*K5+J7*K7+J9*K9+J9*K9+J10*K10+J11*K11+J13*K13+J14*K14+J15*K15+J17*K17+J18*K18+J19*K19+M4*N4+M5*N5+M7*N7+M11*N11+M14*N14+M17*N17+M19*N19 -> 0 | S23: HECTARES DEVIDOS | T23: =R4*S4+R5*S5+R9*S9+R12*S12+R14*S14+R16*S16+R17*S17+R19*S19 -> 0
O24: VALOR A SER PAGO | P24: =IF(P22<>"Não se aplica",P22,IF(P21<>"Não se aplica",P21,P20)) -> Informar Município | S24: VALOR A SER PAGO | T24: =IF(T22<>"Não se aplica",T22,IF(T21<>"Não se aplica",T21,T20)) -> Informar Município
O25: VALOR POR HECTARE DEVIDO | P25: =IFERROR(P24/P23,0) -> 0 | S25: VALOR POR HECTARE DEVIDO | T25: =IFERROR(T24/T23,0) -> 0

Sheet Calculadora Linear
D2: SIMULADOR | H2: Compensação por Danos: supressão SEM autorização ou licença - arts. 14 (pré 12/2019) e 15 (pós 12/2019) da Lei estadual nº 21.231 | K2: Compensação Florestal: supressão SEM autorização ou licença - arts. 14 (pré 12/2019) e 15 (pós 12/2019) da Lei estadual nº 21.231 | P2: Compensação florestal autorizada - arts. 21 e 23 da Lei estadual nº 21.231
D3: VALOR ESTADUAL MÉDIO POR HECTARE | E3: TOTAL DESMATADO/ha | F3: FATOR CLASSE ÁREA DESMATADA - FCA | G3: TIPO DE ÁREA SUPRIMIDA | H3: FATOR MULTIPLICADOR COMPENSAÇÃO POR DANOS ATÉ 12/2019 - FMD-1 | I3: ÁREA SUPRIMIDA (ha) | J3: VALOR PARCIAL CORRESPONDENTE | K3: FATOR MULTIPLICADOR COMPENSAÇÃO FLORESTAL ATÉ 12/2019 - FMF-1 | L3: ÁREA SUPRIMIDA (ha) | M3: VALOR PARCIAL CORRESPONDENTE | N3: VALOR DA COMPENSAÇÃO | P3: FATOR MULTIPLICADOR COMPENSAÇÃO FLORESTAL | Q3: ÁREA SUPRIMIDA (ha) | R3: VALOR PARCIAL CORRESPONDENTE
D4: Exercício 2024 | F4: =IF(ISBLANK(E4),"Informar total desmatado/ha", IF(E4<=20,"Ate 20 (vinte) hectares", IF(E4<=50,"Acima de 20 (vinte) e ate 50 (cinquenta) hectares", IF(E4<=100,"Acima de 50 (cinquenta) e ate 100 (cem) hectares", IF(E4<=500,"Acima de 100 (cem) e ate 500 (quinhentos) hectares", IF(E4>500,"Acima de 500 (quinhentos) hectares", "Informar Total desmatado/ha")))))) -> Informar total desmatado/ha | G4: Área Passível | H4: 1 | J4: =IFERROR($D$5*$F$5*$H4*$I4,0) -> 0 | K4: 1 | M4: =IFERROR($D$5*$F$5*$K4*$L4,0) -> 0 | N4: =J4+M4 -> 0 | P4: 1 | R4: =IFERROR($D$5*$F$5*$P4*$Q4,0) -> 0
D5: 17285.25 | F5: =SUMIF(Fatores!$A:$A,'Calculadora Linear'!F4,Fatores!$B:$B) -> 0 | G5: APP/ uso restrito com intervenção permitida por lei - atividade ou obra de utilidade pública ou interesse social. Lei nº 12.651/2012, art. 3º, IX, alíneas e), f), g). | H5: 1 | J5: =IFERROR($D$5*$F$5*$H5*$I5,0) -> 0 | K5: 1 | M5: =IFERROR($D$5*$F$5*$K5*$L5,0) -> 0 | N5: =J5+M5 -> 0 | P5: 1 | R5: =IFERROR($D$5*$F$5*$P5*$Q5,0) -> 0
G6: APP/ uso restrito com intervenção permitida por lei - atividade ou obra de baixo impacto ou interesse social. Lei nº 12.651/2012, art. 3º, IX, alíneas a), b), c), d).
G7: APP/ uso restrito com intervenção NÃO permitida por lei. | H7: 2 | J7: =IFERROR($D$5*$F$5*$H7*$I7,0) -> 0 | K7: 1 | M7: =IFERROR($D$5*$F$5*$K6*$L6,0) -> 0 | N7: =J7+M7 -> 0
G8: RL com intervenção permitida por lei. Lei nº 12.651/2012, art. 3º, IX, alíneas a), b), c), d) ou pesquisa científica.
G9: RL com intervenção permitida por lei: utilidade pública e interesse social conforme Lei nº 12.651/2012, art. 3º, IX, alíneas e), f), g), exploração mineral ou construção de barragens mediante licenciamento. | H9: 1 | J9: =IFERROR($D$5*$F$5*$H9*$I9,0) -> 0 | N9: =J9+M9 -> 0 | P9: 1 | R9: =IFERROR($D$5*$F$5*$P9*$Q9,0) -> 0
G10: RL com intervenção NÃO permitida por lei. | H10: 1 | J10: =IFERROR($D$5*$F$5*$H10*$I10,0) -> 0 | N10: =J10+M10 -> 0
G11: UC integral que admita supressão de vegetação nativa. | H11: 2 | J11: =IFERROR($D$5*$F$5*$H11*$I11,0) -> 0 | K11: 1 | M11: =IFERROR($D$5*$F$5*$K11*$L11,0) -> 0 | N11: =J11+M11 -> 0
G12: UC integral que admita supressão de vegetação nativa, obrigatoriamente para implantação de obras ou serviços de utilidade pública. | P12: 2 | R12: =IFERROR($D$5*$F$5*$P12*$Q12,0) -> 0
G13: UC integral que NÃO admita supressão de vegetação nativa. | H13: 3 | J13: =IFERROR($D$5*$F$5*$H13*$I13,0) -> 0 | N13: =J13+M13 -> 0
G14: UC de uso sustentável que admita supressão de vegetação nativa. | H14: 1 | J14: =IFERROR($D$5*$F$5*$H14*$I14,0) -> 0 | K14: 1 | M14: =IFERROR($D$5*$F$5*$K14*$L14,0) -> 0 | N14: =J14+M14 -> 0 | P14: 1 | R14: =IFERROR($D$5*$F$5*$P14*$Q14,0) -> 0
G15: UC de uso sustentável que NÃO admita supressão de vegetação nativa. | H15: 3 | J15: =IFERROR($D$5*$F$5*$H15*$I15,0) -> 0 | N15: =J15+M15 -> 0
G16: UC de uso sustentável que NÃO admita supressão de vegetação nativa, obrigatoriamente para conversão do uso do solo mediante utilidade pública e interesse social. | P16: 1 | R16: =IFERROR($D$5*$F$5*$P16*$Q16,0) -> 0
G17: APA em zona que admita supressão de vegetação nativa, conforme Plano de Manejo. | H17: 1 | J17: =IFERROR($D$5*$F$5*$H17*$I17,0) -> 0 | K17: 1 | M17: =IFERROR($D$5*$F$5*$K17*$L17,0) -> 0 | N17: =J17+M17 -> 0 | P17: 1 | R17: =IFERROR($D$5*$F$5*$P17*$Q17,0) -> 0
G18: APA em zona que NÃO admita supressão de vegetação nativa, conforme Plano de Manejo. | H18: 2 | J18: =IFERROR($D$5*$F$5*$H18*$I18,0) -> 0 | N18: =J18+M18 -> 0
G19: Zona de Amortecimento. | H19: 1.5 | J19: =IFERROR($D$5*$F$5*$H19*$I19,0) -> 0 | K19: 1 | M19: =IFERROR($D$5*$F$5*$K19*$L19,0) -> 0 | N19: =J19+M19 -> 0 | P19: 1 | R19: =IFERROR($D$5*$F$5*$K15*$L15,0) -> 0
M20: VALOR A SER PAGO | N20: =N4+N5+N7+N9+N10+N11+N13+N14+N15+N17+N18+N19 -> 0 | Q20: VALOR A SER PAGO | R20: =R4+R5+R9+R12+R14+R16+R17+R19 -> 0
M21: HECTARES DEVIDOS | N21: =H4*I4+H5*I5+H7*I7+H9*I9+H10*I10+H11*I11+H13*I13+H14*I14+H15*I15+H17*I17+H18*I18+H19*I19+K4*L4+K5*L5+K7*L7+K11*L11+K14*L14+K17*L17+K19*L19 -> 0 | Q21: HECTARES DEVIDOS | R21: =P4*Q4+P5*Q5+P9*Q9+P12*Q12+P14*Q14+P16*Q16+P17*Q17+P19*Q19 -> 0
M22: VALOR POR HECTARE DEVIDO | N22: =IFERROR(N20/N21,0) -> 0 | Q22: VALOR POR HECTARE DEVIDO | R22: =IFERROR(R20/R21,0) -> 0

Sheet Fatores
A1: FATOR PORTE DO IMÓVEL - FPI | B1: FATOR | D1: MUNICÍPIO | E1: MÓDULO FISCAL
A2: Pequeno (ate 4 modulos fiscais) | B2: 0.1 | D2: ABADIA DE GOIAS | E2: 24
A3: Medio (superior a 4 e ate 15 modulos fiscais) | B3: 0.3 | D3: ABADIANIA | E3: 40
A4: Grande (superior a 15 modulos fiscais) | B4: 0.5 | D4: ACREUNA | E4: 30
D5: ADELANDIA | E5: 22
A6: FATOR DE CLASSE DA ÁREA DESMATADA - FCA | B6: FATOR | D6: AGUA FRIA DE GOIAS | E6: 35
A7: Ate 20 (vinte) hectares | B7: 0.4 | D7: AGUA LIMPA | E7: 45
A8: Acima de 20 (vinte) e ate 50 (cinquenta) hectares | B8: 0.8 | D8: AGUAS LINDAS DE GOIAS | E8: 40
A9: Acima de 50 (cinquenta) e ate 100 (cem) hectares | B9: 1.2 | D9: ALEXANIA | E9: 30
A10: Acima de 100 (cem) e ate 500 (quinhentos) hectares | B10: 1.6 | D10: ALOANDIA | E10: 35
A11: Acima de 500 (quinhentos) hectares | B11: 2 | D11: ALTO HORIZONTE | E11: 60
D12: ALTO PARAISO DE GOIAS | E12: 70
D13: ALVORADA DO NORTE | E13: 70
D14: AMARALINA | E14: 60
D15: AMERICANO DO BRASIL | E15: 22
D16: AMORINOPOLIS | E16: 20
D17: ANAPOLIS | E17: 16
D18: ANHANGUERA | E18: 45
D19: ANICUNS | E19: 22
D20: APARECIDA DE GOIANIA | E20: 22
D21: APARECIDA DO RIO DOCE | E21: 40
D22: APORE | E22: 40
D23: ARACU | E23: 22
... D247: VILA PROPICIO | E247: 35

Sheet VTN2025
A1: VALORES DE TERRA NUA - EXERCICIO 2025
A2: UF | B2: Nome Municipio | C2: Lavoura Aptidao Boa | D2: Lavoura Aptidao Regular | E2: Lavoura Aptidao Restrita | F2: Pastagem Plantada | G2: Silvicultura ou Pastagem Natural | H2: Preservacao da Fauna e da Flora | I2: MEDIA
A3: GO | B3: ABADIA DE GOIAS | C3: 51060.35 | D3: 35742.25 | E3: 25530.18 | F3: 20271.72 | G3: 13514.48 | H3: 6757.24 | I3: =AVERAGE(C3:H3) -> 25479.37
A4: GO | B4: ABADIANIA | C4: 39066.45 | D4: 26729.68 | E4: 20561.29 | F4: 16449.03 | G4: 12336.77 | H4: 8224.52 | I4: =AVERAGE(C4:H4) -> 20561.29
A5: GO | B5: ACREUNA | C5: 36226.78 | D5: 29159.27 | E5: 21822.27 | F5: 29159.27 | G5: 19349.46 | H5: 19348.17 | I5: =AVERAGE(C5:H5) -> 25844.203
A6: GO | B6: ADELANDIA | C6: 28925.62 | D6: 26684.94 | E6: 25055.3 | F6: 21796.09 | G6: 18944.26 | H6: 14666.53 | I6: =AVERAGE(C6:H6) -> 22678.79
A7: GO | B7: AGUA FRIA DE GOIAS | C7: 12152.04 | D7: 10244.23 | E7: 8707.6 | F7: 5392.48 | G7: 4561.14 | H7: 3404.01 | I7: =AVERAGE(C7:H7) -> 7410.25
A8: GO | B8: ALEXANIA | C8: 23437.59 | D8: 16036.24 | E8: 12335.57 | F8: 9868.46 | G8: 7401.35 | H8: 4933.9 | I8: =AVERAGE(C8:H8) -> 12335.518
A9: GO | B9: ALTO HORIZONTE | C9: 8390.06 | D9: 7131.62 | E9: 5418.23 | F9: 5031.72 | G9: 4257.61 | H9: 2322.33 | I9: =AVERAGE(C9:H9) -> 5425.2617
A10: GO | B10: ALTO PARAISO DE GOIAS | C10: 15150.6 | D10: 12878 | E10: 9568.79 | F10: 4749.78 | G10: 3521.06 | H10: 1760.54 | I10: =AVERAGE(C10:H10) -> 7938.1283
A11: GO | B11: AMARALINA | C11: 9041.48 | D11: 7685.26 | E11: 6532.47 | F11: 5552.6 | G11: 4719.71 | H11: 3775.77 | I11: =AVERAGE(C11:H11) -> 6217.8817
A12: GO | B12: AMERICANO DO BRASIL | C12: 43967.57 | D12: 37719.77 | E12: 33925.37 | F12: 32988.87 | G12: 29321.96 | H12: 18668.63 | I12: =AVERAGE(C12:H12) -> 32765.362
A13: GO | B13: AMORINOPOLIS | C13: 19210.66 | D13: 17169.64 | E13: 15779.97 | F13: 14325.41 | G13: 10625.83 | H13: 8011.1 | I13: =AVERAGE(C13:H13) -> 14187.102
A14: GO | B14: ANICUNS | C14: 34485.17 | D14: 31074.58 | E14: 29584.82 | F14: 26608.75 | G14: 22998.15 | H14: 18732.44 | I14: =AVERAGE(C14:H14) -> 27247.318
... A35: GO | B35: CABECEIRAS | C35: 33915.68 | D35: 25951.48 | E35: 11305.84 | F35: 11305.84 | G35: 10175.26 | H35: 4522.33 | I35: =AVERAGE(C35:H35) -> 16196.072
A36: GO | B36: CACHOEIRA ALTA | C36: 11570.24 | D36: 10123.96 | E36: 8677.68 | F36: 9100 | G36: 9100 | H36: s/informação | I36: =AVERAGE(C35:H36) -> 13249.846
A37: GO | B37: CACHOEIRA DE GOIAS | C37: 37740.26 | D37: 26418.18 | E37: 18870.13 | F37: 14983.45 | G37: 9988.96 | H37: 4994.48 | I37: =AVERAGE(C37:H37) -> 18832.577
A38: GO | B38: CACU | C38: 33117.76 | D38: 22659.52 | E38: 17430.4 | F38: 15373.6 | G38: 11310.57 | H38: 7686.78 | I38: =AVERAGE(C38:H38) -> 17929.772
A39: GO | B39: CAIAPONIA | C39: 15155.76 | D39: 10216.67 | E39: 7140.7 | F39: 4550.85 | G39: 4266.96 | H39: 4150.41 | I39: =AVERAGE(C39:H39) -> 7580.225
A40: GO | B40: CALDAS NOVAS | C40: 19173.86 | D40: 15186.67 | E40: 13585.17 | F40: 11994.71 | G40: 11199.48 | H40: 7996.47 | I40: =AVERAGE(C40:H40) -> 13189.393
A41: GO | B41: CAMPINACU | C41: 6905.56 | D41: 6598.65 | E41: 5370.99 | F41: 4143.34 | G41: 3836.42 | H41: 3069.14 | I41: =AVERAGE(C41:H41) -> 4987.35
A42: GO | B42: CAMPINORTE | C42: 10957.78 | D42: 9314.11 | E42: 7916.99 | F42: 6729.44 | G42: 5720.02 | H42: 4576.02 | I42: =AVERAGE(C42:H42) -> 7535.7267
A43: GO | B43: CAMPO ALEGRE DE GOIAS | C43: 21729.16 | D43: 18284.53 | E43: 15848.18 | F43: 12809.23 | G43: 12809.23 | H43: 5827.21 | I43: =AVERAGE(C43:H43) -> 14551.257
A44: GO | B44: CAMPO LIMPO DE GOIAS | C44: 35907.42 | D44: 28253.47 | E44: 21733.44 | F44: 17386.75 | G44: 13040.06 | H44: 8693.37 | I44: =AVERAGE(C44:H44) -> 20835.752
A45: GO | B45: CAMPOS BELOS | C45: 8167.37 | D45: 6942.27 | E45: 5900.93 | F45: 5015.79 | G45: 4236.43 | H45: 3410.74 | I45: =AVERAGE(C45:H45) -> 5612.255
A46: GO | B46: CAMPOS VERDES | C46: 8228.07 | D46: 7357.33 | E46: 6741.45 | F46: 6768.44 | G46: 5283.41 | H46: 3939.2 | I46: =AVERAGE(C46:H46) -> 6386.3167
A47: GO | B47: CASTELANDIA | C47: 48702.17 | D47: 45320.18 | E47: 39265.15 | F47: 35926.2 | G47: 32531.82 | H47: 25321.46 | I47: =AVERAGE(C47:H47) -> 37844.497
A48: GO | B48: CATALAO | C48: 29000 | D48: 26500 | E48: 24500 | F48: 22500 | G48: 20000 | H48: 7000 | I48: =AVERAGE(C48:H48) -> 21583.333
... A189: GO | B189: VILA PROPICIO | C189: 27497.19 | D189: 19104.21 | E189: 8804.08 | F189: 8804.08 | G189: 5742.15 | H189: 3825.71 | I189: =AVERAGE(C189:H189) -> 12296.237
I191: MEDIA ESTADUAL
I192: =AVERAGE(I2:I189) -> 17285.249

Sheet Médias2025
A1: CIDADE | B1: FROTEIRA | C1: Valor Terra Nua / ha | D1: MÉDIA FRONTEIRAS | E1: MÉDIA ESTADUAL (ABA "VTN2025")
A2: Abadia de Goias | B2: Aparecida de Goiania | C2: =IFERROR(VLOOKUP(B2,'VTN2025'!B:I,8,FALSE),"-") -> - | D2: =AVERAGEIF($A:$A,A2,$C:$C) -> 35312.424 | E2: 17285.25
A3: Abadia de Goias | B3: Aragoiania | C3: =IFERROR(VLOOKUP(B3,'VTN2025'!B:I,8,FALSE),"-") -> 28728.082 | D3: =AVERAGEIF($A:$A,A3,$C:$C) -> 35312.424
A4: Abadia de Goias | B4: Goiania | C4: =IFERROR(VLOOKUP(B4,'VTN2025'!B:I,8,FALSE),"-") -> 64897.673 | D4: =AVERAGEIF($A:$A,A4,$C:$C) -> 35312.424
A5: Abadia de Goias | B5: Guapo | C5: =IFERROR(VLOOKUP(B5,'VTN2025'!B:I,8,FALSE),"-") -> 21065.23 | D5: =AVERAGEIF($A:$A,A5,$C:$C) -> 35312.424
A6: Abadia de Goias | B6: Trindade | C6: =IFERROR(VLOOKUP(B6,'VTN2025'!B:I,8,FALSE),"-") -> 26558.712 | D6: =AVERAGEIF($A:$A,A6,$C:$C) -> 35312.424
A7: Abadiania | B7: Alexania | C7: =IFERROR(VLOOKUP(B7,'VTN2025'!B:I,8,FALSE),"-") -> 12335.518 | D7: =AVERAGEIF($A:$A,A7,$C:$C) -> 16428.56
A8: Abadiania | B8: Anapolis | C8: =IFERROR(VLOOKUP(B8,'VTN2025'!B:I,8,FALSE),"-") -> - | D8: =AVERAGEIF($A:$A,A8,$C:$C) -> 16428.56
A9: Abadiania | B9: Corumba de Goias | C9: =IFERROR(VLOOKUP(B9,'VTN2025'!B:I,8,FALSE),"-") -> - | D9: =AVERAGEIF($A:$A,A9,$C:$C) -> 16428.56
A10: Abadiania | B10: Gameleira de Goias | C10: =IFERROR(VLOOKUP(B10,'VTN2025'!B:I,8,FALSE),"-") -> - | D10: =AVERAGEIF($A:$A,A10,$C:$C) -> 16428.56
A11: Abadiania | B11: Pirenopolis | C11: =IFERROR(VLOOKUP(B11,'VTN2025'!B:I,8,FALSE),"-") -> - | D11: =AVERAGEIF($A:$A,A11,$C:$C) -> 16428.56
A12: Abadiania | B12: Silvania | C12: =IFERROR(VLOOKUP(B12,'VTN2025'!B:I,8,FALSE),"-") -> 20521.602 | D12: =AVERAGEIF($A:$A,A12,$C:$C) -> 16428.56
A13: Acreuna | B13: Edeia | C13: =IFERROR(VLOOKUP(B13,'VTN2025'!B:I,8,FALSE),"-") -> 36128.4 | D13: =AVERAGEIF($A:$A,A13,$C:$C) -> 22250.207
A14: Acreuna | B14: Indiara | C14: =IFERROR(VLOOKUP(B14,'VTN2025'!B:I,8,FALSE),"-") -> 20209.003 | D14: =AVERAGEIF($A:$A,A14,$C:$C) -> 22250.207
... A60: Amorinopolis | B60: Ivolandia | C60: =IFERROR(VLOOKUP(B60,'VTN2025'!B:I,8,FALSE),"-") -> 12237.195 | D60: =AVERAGEIF($A:$A,A60,$C:$C) -> 12145.483
A61: Anhanguera | B61: Araguari | C61: =IFERROR(VLOOKUP(B61,'VTN2025'!B:I,8,FALSE),"-") -> - | D61: 15732.82 | E61: Média estadual
A62: Anhanguera | B62: Cumari | C62: =IFERROR(VLOOKUP(B62,'VTN2025'!B:I,8,FALSE),"-") -> - | D62: 15732.82 | E62: Média estadual
A63: Anicuns | B63: Adelandia | C63: =IFERROR(VLOOKUP(B63,'VTN2025'!B:I,8,FALSE),"-") -> 22678.79 | D63: =AVERAGEIF($A:$A,A63,$C:$C) -> 26960.121
A64: Anicuns | B64: Americano do Brasil | C64: =IFERROR(VLOOKUP(B64,'VTN2025'!B:I,8,FALSE),"-") -> 32765.362 | D64: =AVERAGEIF($A:$A,A64,$C:$C) -> 26960.121
A65: Anicuns | B65: Avelinopolis | C65: =IFERROR(VLOOKUP(B65,'VTN2025'!B:I,8,FALSE),"-") -> 27850.557 | D65: =AVERAGEIF($A:$A,A65,$C:$C) -> 26960.121
A66: Anicuns | B66: Itaberai | C66: =IFERROR(VLOOKUP(B66,'VTN2025'!B:I,8,FALSE),"-") -> 28687.102 | D66: =AVERAGEIF($A:$A,A66,$C:$C) -> 26960.121
A67: Anicuns | B67: Mossamedes | C67: =IFERROR(VLOOKUP(B67,'VTN2025'!B:I,8,FALSE),"-") -> 22097 | D67: =AVERAGEIF($A:$A,A67,$C:$C) -> 26960.121
A68: Anicuns | B68: Nazario | C68: =IFERROR(VLOOKUP(B68,'VTN2025'!B:I,8,FALSE),"-") -> - | D68: =AVERAGEIF($A:$A,A68,$C:$C) -> 26960.121
A69: Anicuns | B69: Sao Luis de Montes Belos | C69: =IFERROR(VLOOKUP(B69,'VTN2025'!B:I,8,FALSE),"-") -> 18405.72 | D69: =AVERAGEIF($A:$A,A69,$C:$C) -> 26960.121
A70: Anicuns | B70: Turvania | C70: =IFERROR(VLOOKUP(B70,'VTN2025'!B:I,8,FALSE),"-") -> 36236.317 | D70: =AVERAGEIF($A:$A,A70,$C:$C) -> 26960.121
A71: Anapolis | B71: Abadiania | C71: =IFERROR(VLOOKUP(B71,'VTN2025'!B:I,8,FALSE),"-") -> 20561.29 | D71: =AVERAGEIF($A:$A,A71,$C:$C) -> 21167.162
A72: Anapolis | B72: Campo Limpo de Goias | C72: =IFERROR(VLOOKUP(B72,'VTN2025'!B:I,8,FALSE),"-") -> 20835.752 | D72: =AVERAGEIF($A:$A,A72,$C:$C) -> 21167.162
A73: Anapolis | B73: Gameleira de Goias | C73: =IFERROR(VLOOKUP(B73,'VTN2025'!B:I,8,FALSE),"-") -> - | D73: =AVERAGEIF($A:$A,A73,$C:$C) -> 21167.162
A74: Anapolis | B74: Goianapolis | C74: =IFERROR(VLOOKUP(B74,'VTN2025'!B:I,8,FALSE),"-") -> 15196.01 | D74: =AVERAGEIF($A:$A,A74,$C:$C) -> 21167.162
... A406: Corrego do Ouro | B406: Sao Luis de Montes Belos | C406: =IFERROR(VLOOKUP(B406,'VTN2025'!B:I,8,FALSE),"-") -> 18405.72 | D406: =AVERAGEIF($A:$A,A406,$C:$C) -> 17891.598
A407: Damianopolis | B407: Buritinopolis | C407: =IFERROR(VLOOKUP(B407,'VTN2025'!B:I,8,FALSE),"-") -> - | D407: 15732.82 | E407: Média estadual
A408: Damianopolis | B408: Mambai | C408: =IFERROR(VLOOKUP(B408,'VTN2025'!B:I,8,FALSE),"-") -> - | D408: 15732.82 | E408: Média estadual
A409: Damianopolis | B409: Sitio d'Abadia | C409: =IFERROR(VLOOKUP(B409,'VTN2025'!B:I,8,FALSE),"-") -> - | D409: 15732.82 | E409: Média estadual
A410: Damolandia | B410: Brazabrantes | C410: =IFERROR(VLOOKUP(B410,'VTN2025'!B:I,8,FALSE),"-") -> 29748.622 | D410: =AVERAGEIF($A:$A,A410,$C:$C) -> 31792.368
A411: Damolandia | B411: Inhumas | C411: =IFERROR(VLOOKUP(B411,'VTN2025'!B:I,8,FALSE),"-") -> 31249.99 | D411: =AVERAGEIF($A:$A,A411,$C:$C) -> 31792.368
A412: Damolandia | B412: Itaucu | C412: =IFERROR(VLOOKUP(B412,'VTN2025'!B:I,8,FALSE),"-") -> 30042.522 | D412: =AVERAGEIF($A:$A,A412,$C:$C) -> 31792.368
A413: Damolandia | B413: Nova Veneza | C413: =IFERROR(VLOOKUP(B413,'VTN2025'!B:I,8,FALSE),"-") -> 46389.418 | D413: =AVERAGEIF($A:$A,A413,$C:$C) -> 31792.368
A414: Damolandia | B414: Ouro Verde de Goias | C414: =IFERROR(VLOOKUP(B414,'VTN2025'!B:I,8,FALSE),"-") -> 26571.99 | D414: =AVERAGEIF($A:$A,A414,$C:$C) -> 31792.368
A415: Damolandia | B415: Petrolina de Goias | C415: =IFERROR(VLOOKUP(B415,'VTN2025'!B:I,8,FALSE),"-") -> 26751.667 | D415: =AVERAGEIF($A:$A,A415,$C:$C) -> 31792.368
A416: Davinopolis | B416: Catalao | C416: =IFERROR(VLOOKUP(B416,'VTN2025'!B:I,8,FALSE),"-") -> 21583.333 | D416: =AVERAGEIF($A:$A,A416,$C:$C) -> 21583.333
...
